Workbook

Sheet README
A1: TMMIN Next-Level Kaizen: Case Model & Answer Kit
A2: Working file for the team. Every number traces to a case exhibit or a labeled assumption.
A4: Colour legend
A5: Blue text | B5: Hardcoded input (from the case or a team assumption)
A6: Black text | B6: Formula, do not overwrite
A7: Green text | B7: Link from another tab
A8: Yellow fill | B8: Key assumption the team must justify or change
A9: Red fill | B9: VERIFY against the original casebook PDF (text came through garbled)
A11: Tab map
A12: WBS | B12: Work breakdown: who does what, which day, done criteria, hours, daily Gantt. Start here.
A13: Answer_Guide | B13: How to answer each sub-question, deck storyline with action titles, Q&A prep
A14: Ideation | B14: 8 idea options with case gaps, TPS anchor, Toyota precedent, references, weighted scoring
A15: Simulation | B15: Idea tests run in Python: closed-loop quality sim, financial Monte Carlo, roadmap strategies, tornado
A16: Exhibits | B16: Clean re-typed case data (Exhibits 1, 3-9). Fix red cells first
A17: Assumptions | B17: All model inputs + benchmark evidence for each lever; pilot-light phasing
A18: Model | B18: Savings by lever, investment, running cost, NPV, IRR, payback for 3 scenarios (2026-2030)
A19: Dashboard | B19: Scenario summary and charts for the financial slide
A20: Breakeven | B20: How much saving pays back Rp40-120B, plus NPV sensitivity grid
A21: Capability | B21: Workforce model: engineer skill levels, improvement time, know-how, ramp-up to 2030
A22: KPIs | B22: KPI tree with baselines from exhibits and suggested pilot / 2030 targets
A23: Roadmap | B23: Phased 2026-2030 roadmap template across workstreams
... A25: QA_Bank | B25: 15 likely judge questions with answer outline, evidence and owner
A27: How to use
A28: 1. Day 1: type names in WBS, re-type every red cell in Exhibits from the PDF.
A29: 2. Day 2-3: re-score Ideation as a team, lock ONE integrated idea + one pilot area by end of Day 3.
A30: 3. Day 3-4: replace yellow assumptions with numbers you can defend (Assumptions column G shows benchmarks found so far).
A31: 4. Day 5: re-run run_tests.py so the Simulation tab matches your final assumptions.
A32: 5. Dashboard, Breakeven and Capability update automatically. Example values in yellow cells are placeholders, not facts.

Sheet WBS
A1: Work breakdown structure: 7 days, 3 members
A2: Type your names in the yellow cells. Owner = accountable (hours counted); Support = helps. Update Status daily in the stand-up. Daily load is red above 6.5 hours.
A4: Code | B4: Name | C4: Role & accountable for | D4: Hours owned | E4: Tasks owned | F4: Tasks done | J4: Load (h/day) | K4: D1 | L4: D2 | M4: D3 | N4: D4 | O4: D5 | P4: D6 | Q4: D7
A5: M1 | B5: [Name M1] | C5: Lead, storyline & people: Owns problem framing, vision, idea decision, mindset & knowledge mechanism, governance, risks, exec summary, speaking script, mocks, submission | D5: =SUMIF($D$13:$D$70,A5,$H$13:$H$70) | E5: =COUNTIF($D$13:$D$70,A5) | F5: =COUNTIFS($D$13:$D$70,A5,$J$13:$J$70,"Done") | J5: M1 | K5: =SUMPRODUCT(($D$13:$D$70=$A5)*($F$13:$F$70<=1)*($G$13:$G$70>=1),$H$13:$H$70/($G$13:$G$70-$F$13:$F$70+1)) | L5: =SUMPRODUCT(($D$13:$D$70=$A5)*($F$13:$F$70<=2)*($G$13:$G$70>=2),$H$13:$H$70/($G$13:$G$70-$F$13:$F$70+1)) | M5: =SUMPRODUCT(($D$13:$D$70=$A5)*($F$13:$F$70<=3)*($G$13:$G$70>=3),$H$13:$H$70/($G$13:$G$70-$F$13:$F$70+1)) | N5: =SUMPRODUCT(($D$13:$D$70=$A5)*($F$13:$F$70<=4)*($G$13:$G$70>=4),$H$13:$H$70/($G$13:$G$70-$F$13:$F$70+1)) | O5: =SUMPRODUCT(($D$13:$D$70=$A5)*($F$13:$F$70<=5)*($G$13:$G$70>=5),$H$13:$H$70/($G$13:$G$70-$F$13:$F$70+1)) | P5: =SUMPRODUCT(($D$13:$D$70=$A5)*($F$13:$F$70<=6)*($G$13:$G$70>=6),$H$13:$H$70/($G$13:$G$70-$F$13:$F$70+1)) | Q5: =SUMPRODUCT(($D$13:$D$70=$A5)*($F$13:$F$70<=7)*($G$13:$G$70>=7),$H$13:$H$70/($G$13:$G$70-$F$13:$F$70+1))
A6: M2 | B6: [Name M2] | C6: Operations, TPS & roadmap: Owns gap heat map, root cause, system diagram, day-in-the-life, build-vs-partner, TPS fit, roadmap, slide template and design polish | D6: =SUMIF($D$13:$D$70,A6,$H$13:$H$70) | E6: =COUNTIF($D$13:$D$70,A6) | F6: =COUNTIFS($D$13:$D$70,A6,$J$13:$J$70,"Done") | J6: M2 | K6: =SUMPRODUCT(($D$13:$D$70=$A6)*($F$13:$F$70<=1)*($G$13:$G$70>=1),$H$13:$H$70/($G$13:$G$70-$F$13:$F$70+1)) | L6: =SUMPRODUCT(($D$13:$D$70=$A6)*($F$13:$F$70<=2)*($G$13:$G$70>=2),$H$13:$H$70/($G$13:$G$70-$F$13:$F$70+1)) | M6: =SUMPRODUCT(($D$13:$D$70=$A6)*($F$13:$F$70<=3)*($G$13:$G$70>=3),$H$13:$H$70/($G$13:$G$70-$F$13:$F$70+1)) | N6: =SUMPRODUCT(($D$13:$D$70=$A6)*($F$13:$F$70<=4)*($G$13:$G$70>=4),$H$13:$H$70/($G$13:$G$70-$F$13:$F$70+1)) | O6: =SUMPRODUCT(($D$13:$D$70=$A6)*($F$13:$F$70<=5)*($G$13:$G$70>=5),$H$13:$H$70/($G$13:$G$70-$F$13:$F$70+1)) | P6: =SUMPRODUCT(($D$13:$D$70=$A6)*($F$13:$F$70<=6)*($G$13:$G$70>=6),$H$13:$H$70/($G$13:$G$70-$F$13:$F$70+1)) | Q6: =SUMPRODUCT(($D$13:$D$70=$A6)*($F$13:$F$70<=7)*($G$13:$G$70>=7),$H$13:$H$70/($G$13:$G$70-$F$13:$F$70+1))
A7: M3 | B7: [Name M3] | C7: Quant, finance & evidence: Owns exhibits data, benchmarks, assumptions, Model, simulation re-runs, capability model, KPIs, appendix, number tie-out, Q&A bank | D7: =SUMIF($D$13:$D$70,A7,$H$13:$H$70) | E7: =COUNTIF($D$13:$D$70,A7) | F7: =COUNTIFS($D$13:$D$70,A7,$J$13:$J$70,"Done") | J7: M3 | K7: =SUMPRODUCT(($D$13:$D$70=$A7)*($F$13:$F$70<=1)*($G$13:$G$70>=1),$H$13:$H$70/($G$13:$G$70-$F$13:$F$70+1)) | L7: =SUMPRODUCT(($D$13:$D$70=$A7)*($F$13:$F$70<=2)*($G$13:$G$70>=2),$H$13:$H$70/($G$13:$G$70-$F$13:$F$70+1)) | M7: =SUMPRODUCT(($D$13:$D$70=$A7)*($F$13:$F$70<=3)*($G$13:$G$70>=3),$H$13:$H$70/($G$13:$G$70-$F$13:$F$70+1)) | N7: =SUMPRODUCT(($D$13:$D$70=$A7)*($F$13:$F$70<=4)*($G$13:$G$70>=4),$H$13:$H$70/($G$13:$G$70-$F$13:$F$70+1)) | O7: =SUMPRODUCT(($D$13:$D$70=$A7)*($F$13:$F$70<=5)*($G$13:$G$70>=5),$H$13:$H$70/($G$13:$G$70-$F$13:$F$70+1)) | P7: =SUMPRODUCT(($D$13:$D$70=$A7)*($F$13:$F$70<=6)*($G$13:$G$70>=6),$H$13:$H$70/($G$13:$G$70-$F$13:$F$70+1)) | Q7: =SUMPRODUCT(($D$13:$D$70=$A7)*($F$13:$F$70<=7)*($G$13:$G$70>=7),$H$13:$H$70/($G$13:$G$70-$F$13:$F$70+1))
A8: Total | D8: =SUM(D5:D7) | E8: =SUM(E5:E7) | F8: =SUM(F5:F7) | J8: Team | K8: =SUM(K5:K7) | L8: =SUM(L5:L7) | M8: =SUM(M5:M7) | N8: =SUM(N5:N7) | O8: =SUM(O5:O7) | P8: =SUM(P5:P7) | Q8: =SUM(Q5:Q7)
C9: Owned hours are balanced within ~4 h. Each member also supports others' tasks (Support column).
A12: WBS | B12: Work package / task | C12: Deliverable & done criteria | D12: Owner | E12: Support | F12: Start day | G12: End day | H12: Hours | I12: Depends on | J12: Status | K12: D1 | L12: D2 | M12: D3 | N12: D4 | O12: D5 | P12: D6 | Q12: D7
A13: 1 | B13: PROJECT MANAGEMENT | F13: 0 | G13: 0
A14: 1.1 | B14: Kick-off: roles, deadline, shared drive, task tracker | C14: Roles agreed, folder + tracker live | D14: M1 | E14: All | F14: 1 | G14: 1 | H14: 2 | J14: Not started | K14: =IF(AND(1>=$F14,1<=$G14),$D14,"") | L14: =IF(AND(2>=$F14,2<=$G14),$D14,"") | M14: =IF(AND(3>=$F14,3<=$G14),$D14,"") | N14: =IF(AND(4>=$F14,4<=$G14),$D14,"") | O14: =IF(AND(5>=$F14,5<=$G14),$D14,"") | P14: =IF(AND(6>=$F14,6<=$G14),$D14,"") | Q14: =IF(AND(7>=$F14,7<=$G14),$D14,"")
A15: 1.2 | B15: Confirm rules in writing (slide limit, format, AI use, judging criteria) | C15: Written confirmation saved | D15: M1 | F15: 1 | G15: 1 | H15: 1 | J15: Not started | K15: =IF(AND(1>=$F15,1<=$G15),$D15,"") | L15: =IF(AND(2>=$F15,2<=$G15),$D15,"") | M15: =IF(AND(3>=$F15,3<=$G15),$D15,"") | N15: =IF(AND(4>=$F15,4<=$G15),$D15,"") | O15: =IF(AND(5>=$F15,5<=$G15),$D15,"") | P15: =IF(AND(6>=$F15,6<=$G15),$D15,"") | Q15: =IF(AND(7>=$F15,7<=$G15),$D15,"")
A16: 1.3 | B16: Daily 15-min stand-up + update this sheet | C16: Status column current every evening | D16: M1 | E16: All | F16: 1 | G16: 7 | H16: 2 | I16: 1.1 | J16: Not started | K16: =IF(AND(1>=$F16,1<=$G16),$D16,"") | L16: =IF(AND(2>=$F16,2<=$G16),$D16,"") | M16: =IF(AND(3>=$F16,3<=$G16),$D16,"") | N16: =IF(AND(4>=$F16,4<=$G16),$D16,"") | O16: =IF(AND(5>=$F16,5<=$G16),$D16,"") | P16: =IF(AND(6>=$F16,6<=$G16),$D16,"") | Q16: =IF(AND(7>=$F16,7<=$G16),$D16,"")
A17: 2 | B17: DIAGNOSE THE PROBLEM (SQ1) | F17: 0 | G17: 0
A18: 2.1 | B18: Re-type exhibits from PDF; clear all red cells | C18: Exhibits tab has zero VERIFY cells | D18: M3 | E18: M2 | F18: 1 | G18: 1 | H18: 2 | J18: Not started | K18: =IF(AND(1>=$F18,1<=$G18),$D18,"") | L18: =IF(AND(2>=$F18,2<=$G18),$D18,"") | M18: =IF(AND(3>=$F18,3<=$G18),$D18,"") | N18: =IF(AND(4>=$F18,4<=$G18),$D18,"") | O18: =IF(AND(5>=$F18,5<=$G18),$D18,"") | P18: =IF(AND(6>=$F18,6<=$G18),$D18,"") | Q18: =IF(AND(7>=$F18,7<=$G18),$D18,"")
A19: 2.2 | B19: Issue tree + problem statement | C19: 1-page issue tree, MECE, agreed by team | D19: M1 | E19: All | F19: 1 | G19: 1 | H19: 3 | I19: 2.1 | J19: Not started | K19: =IF(AND(1>=$F19,1<=$G19),$D19,"") | L19: =IF(AND(2>=$F19,2<=$G19),$D19,"") | M19: =IF(AND(3>=$F19,3<=$G19),$D19,"") | N19: =IF(AND(4>=$F19,4<=$G19),$D19,"") | O19: =IF(AND(5>=$F19,5<=$G19),$D19,"") | P19: =IF(AND(6>=$F19,6<=$G19),$D19,"") | Q19: =IF(AND(7>=$F19,7<=$G19),$D19,"")
A20: 2.3 | B20: Gap heat map: process x cost/quality impact | C20: Heat map slide using Exhibits 4-5 | D20: M2 | E20: M3 | F20: 1 | G20: 2 | H20: 4 | I20: 2.1 | J20: Not started | K20: =IF(AND(1>=$F20,1<=$G20),$D20,"") | L20: =IF(AND(2>=$F20,2<=$G20),$D20,"") | M20: =IF(AND(3>=$F20,3<=$G20),$D20,"") | N20: =IF(AND(4>=$F20,4<=$G20),$D20,"") | O20: =IF(AND(5>=$F20,5<=$G20),$D20,"") | P20: =IF(AND(6>=$F20,6<=$G20),$D20,"") | Q20: =IF(AND(7>=$F20,7<=$G20),$D20,"")
A21: 2.4 | B21: Root cause (5-whys / fishbone) on the 3 complications | C21: Root-cause slide: 'open loops' | D21: M2 | E21: M1 | F21: 2 | G21: 2 | H21: 3 | I21: 2.2 | J21: Not started | K21: =IF(AND(1>=$F21,1<=$G21),$D21,"") | L21: =IF(AND(2>=$F21,2<=$G21),$D21,"") | M21: =IF(AND(3>=$F21,3<=$G21),$D21,"") | N21: =IF(AND(4>=$F21,4<=$G21),$D21,"") | O21: =IF(AND(5>=$F21,5<=$G21),$D21,"") | P21: =IF(AND(6>=$F21,6<=$G21),$D21,"") | Q21: =IF(AND(7>=$F21,7<=$G21),$D21,"")
A22: 2.5 | B22: Benchmark research: Toyota precedents + lever benchmarks | C22: Ideation refs + Assumptions col G complete | D22: M3 | E22: M2 | F22: 2 | G22: 3 | H22: 4 | J22: Not started | K22: =IF(AND(1>=$F22,1<=$G22),$D22,"") | L22: =IF(AND(2>=$F22,2<=$G22),$D22,"") | M22: =IF(AND(3>=$F22,3<=$G22),$D22,"") | N22: =IF(AND(4>=$F22,4<=$G22),$D22,"") | O22: =IF(AND(5>=$F22,5<=$G22),$D22,"") | P22: =IF(AND(6>=$F22,6<=$G22),$D22,"") | Q22: =IF(AND(7>=$F22,7<=$G22),$D22,"")
A23: 2.6 | B23: 2030 vision + 'value beyond cost' statement | C23: Vision slide draft | D23: M1 | E23: M2 | F23: 2 | G23: 2 | H23: 2 | I23: 2.3 | J23: Not started | K23: =IF(AND(1>=$F23,1<=$G23),$D23,"") | L23: =IF(AND(2>=$F23,2<=$G23),$D23,"") | M23: =IF(AND(3>=$F23,3<=$G23),$D23,"") | N23: =IF(AND(4>=$F23,4<=$G23),$D23,"") | O23: =IF(AND(5>=$F23,5<=$G23),$D23,"") | P23: =IF(AND(6>=$F23,6<=$G23),$D23,"") | Q23: =IF(AND(7>=$F23,7<=$G23),$D23,"")
A24: 3 | B24: DESIGN THE IDEA (SQ2) | F24: 0 | G24: 0
A25: 3.1 | B25: Ideation session: re-score 8 options as a team | C25: Scoring matrix updated with team scores | D25: M1 | E25: All | F25: 3 | G25: 3 | H25: 2 | I25: 2.4 | J25: Not started | K25: =IF(AND(1>=$F25,1<=$G25),$D25,"") | L25: =IF(AND(2>=$F25,2<=$G25),$D25,"") | M25: =IF(AND(3>=$F25,3<=$G25),$D25,"") | N25: =IF(AND(4>=$F25,4<=$G25),$D25,"") | O25: =IF(AND(5>=$F25,5<=$G25),$D25,"") | P25: =IF(AND(6>=$F25,6<=$G25),$D25,"") | Q25: =IF(AND(7>=$F25,7<=$G25),$D25,"")
A26: 3.2 | B26: Decide integrated idea + pilot area (decision log) | C26: One-line decision + 3 reasons | D26: M1 | E26: All | F26: 3 | G26: 3 | H26: 1 | I26: 3.1 | J26: Not started | K26: =IF(AND(1>=$F26,1<=$G26),$D26,"") | L26: =IF(AND(2>=$F26,2<=$G26),$D26,"") | M26: =IF(AND(3>=$F26,3<=$G26),$D26,"") | N26: =IF(AND(4>=$F26,4<=$G26),$D26,"") | O26: =IF(AND(5>=$F26,5<=$G26),$D26,"") | P26: =IF(AND(6>=$F26,6<=$G26),$D26,"") | Q26: =IF(AND(7>=$F26,7<=$G26),$D26,"")
A27: 3.3 | B27: System diagram: three closed loops | C27: One clean diagram, reviewed by all | D27: M2 | E27: M1 | F27: 3 | G27: 3 | H27: 3 | I27: 3.2 | J27: Not started | K27: =IF(AND(1>=$F27,1<=$G27),$D27,"") | L27: =IF(AND(2>=$F27,2<=$G27),$D27,"") | M27: =IF(AND(3>=$F27,3<=$G27),$D27,"") | N27: =IF(AND(4>=$F27,4<=$G27),$D27,"") | O27: =IF(AND(5>=$F27,5<=$G27),$D27,"") | P27: =IF(AND(6>=$F27,6<=$G27),$D27,"") | Q27: =IF(AND(7>=$F27,7<=$G27),$D27,"")
A28: 3.4 | B28: Day-in-the-life before/after (operator, team leader, engineer) | C28: Before/after slide | D28: M2 | E28: M1 | F28: 4 | G28: 4 | H28: 3 | I28: 3.2 | J28: Not started | K28: =IF(AND(1>=$F28,1<=$G28),$D28,"") | L28: =IF(AND(2>=$F28,2<=$G28),$D28,"") | M28: =IF(AND(3>=$F28,3<=$G28),$D28,"") | N28: =IF(AND(4>=$F28,4<=$G28),$D28,"") | O28: =IF(AND(5>=$F28,5<=$G28),$D28,"") | P28: =IF(AND(6>=$F28,6<=$G28),$D28,"") | Q28: =IF(AND(7>=$F28,7<=$G28),$D28,"")
A29: 3.5 | B29: Mindset & knowledge mechanism (idea channel, capture, recognition) | C29: Mechanism slide tied to Exhibits 6A/6B | D29: M1 | E29: M2 | F29: 4 | G29: 4 | H29: 3 | I29: 3.2 | J29: Not started | K29: =IF(AND(1>=$F29,1<=$G29),$D29,"") | L29: =IF(AND(2>=$F29,2<=$G29),$D29,"") | M29: =IF(AND(3>=$F29,3<=$G29),$D29,"") | N29: =IF(AND(4>=$F29,4<=$G29),$D29,"") | O29: =IF(AND(5>=$F29,5<=$G29),$D29,"") | P29: =IF(AND(6>=$F29,6<=$G29),$D29,"") | Q29: =IF(AND(7>=$F29,7<=$G29),$D29,"")
A30: 3.6 | B30: Build vs partner logic per component | C30: 2x2 or table slide | D30: M2 | E30: M3 | F30: 4 | G30: 5 | H30: 2 | I30: 3.2 | J30: Not started | K30: =IF(AND(1>=$F30,1<=$G30),$D30,"") | L30: =IF(AND(2>=$F30,2<=$G30),$D30,"") | M30: =IF(AND(3>=$F30,3<=$G30),$D30,"") | N30: =IF(AND(4>=$F30,4<=$G30),$D30,"") | O30: =IF(AND(5>=$F30,5<=$G30),$D30,"") | P30: =IF(AND(6>=$F30,6<=$G30),$D30,"") | Q30: =IF(AND(7>=$F30,7<=$G30),$D30,"")
A31: 3.7 | B31: TPS principle mapping (jidoka, kaizen, standardized work, yokoten) | C31: Mapping table | D31: M2 | F31: 3 | G31: 3 | H31: 1 | I31: 3.3 | J31: Not started | K31: =IF(AND(1>=$F31,1<=$G31),$D31,"") | L31: =IF(AND(2>=$F31,2<=$G31),$D31,"") | M31: =IF(AND(3>=$F31,3<=$G31),$D31,"") | N31: =IF(AND(4>=$F31,4<=$G31),$D31,"") | O31: =IF(AND(5>=$F31,5<=$G31),$D31,"") | P31: =IF(AND(6>=$F31,6<=$G31),$D31,"") | Q31: =IF(AND(7>=$F31,7<=$G31),$D31,"")
A32: 4 | B32: ROADMAP & CAPABILITY (SQ3) | F32: 0 | G32: 0
A33: 4.1 | B33: Phased roadmap with gates (pilot-light) | C33: Roadmap slide with gate criteria | D33: M2 | E33: M3 | F33: 4 | G33: 5 | H33: 3 | I33: 3.2 | J33: Not started | K33: =IF(AND(1>=$F33,1<=$G33),$D33,"") | L33: =IF(AND(2>=$F33,2<=$G33),$D33,"") | M33: =IF(AND(3>=$F33,3<=$G33),$D33,"") | N33: =IF(AND(4>=$F33,4<=$G33),$D33,"") | O33: =IF(AND(5>=$F33,5<=$G33),$D33,"") | P33: =IF(AND(6>=$F33,6<=$G33),$D33,"") | Q33: =IF(AND(7>=$F33,7<=$G33),$D33,"")
A34: 4.2 | B34: Capability plan using Capability tab | C34: Academy design + L3+ targets consistent with KPIs | D34: M3 | E34: M1 | F34: 4 | G34: 5 | H34: 2 | I34: 3.2 | J34: Not started | K34: =IF(AND(1>=$F34,1<=$G34),$D34,"") | L34: =IF(AND(2>=$F34,2<=$G34),$D34,"") | M34: =IF(AND(3>=$F34,3<=$G34),$D34,"") | N34: =IF(AND(4>=$F34,4<=$G34),$D34,"") | O34: =IF(AND(5>=$F34,5<=$G34),$D34,"") | P34: =IF(AND(6>=$F34,6<=$G34),$D34,"") | Q34: =IF(AND(7>=$F34,7<=$G34),$D34,"")
A35: 4.3 | B35: Risk register + mitigations (quantify top risks with Simulation) | C35: Risks tab finalized, top 3 on slide | D35: M1 | E35: M3 | F35: 5 | G35: 5 | H35: 2 | I35: 4.1 | J35: Not started | K35: =IF(AND(1>=$F35,1<=$G35),$D35,"") | L35: =IF(AND(2>=$F35,2<=$G35),$D35,"") | M35: =IF(AND(3>=$F35,3<=$G35),$D35,"") | N35: =IF(AND(4>=$F35,4<=$G35),$D35,"") | O35: =IF(AND(5>=$F35,5<=$G35),$D35,"") | P35: =IF(AND(6>=$F35,6<=$G35),$D35,"") | Q35: =IF(AND(7>=$F35,7<=$G35),$D35,"")
A36: 4.4 | B36: Governance: owners, cadence, partner roles | C36: Governance box on roadmap slide | D36: M1 | E36: M2 | F36: 5 | G36: 5 | H36: 1 | I36: 4.1 | J36: Not started | K36: =IF(AND(1>=$F36,1<=$G36),$D36,"") | L36: =IF(AND(2>=$F36,2<=$G36),$D36,"") | M36: =IF(AND(3>=$F36,3<=$G36),$D36,"") | N36: =IF(AND(4>=$F36,4<=$G36),$D36,"") | O36: =IF(AND(5>=$F36,5<=$G36),$D36,"") | P36: =IF(AND(6>=$F36,6<=$G36),$D36,"") | Q36: =IF(AND(7>=$F36,7<=$G36),$D36,"")
A37: 5 | B37: IMPACT & FINANCIALS (SQ4) | F37: 0 | G37: 0
A38: 5.1 | B38: Defend every yellow assumption with a source or reason | C38: No yellow cell without a note | D38: M3 | E38: M2 | F38: 3 | G38: 4 | H38: 4 | I38: 2.5 | J38: Not started | K38: =IF(AND(1>=$F38,1<=$G38),$D38,"") | L38: =IF(AND(2>=$F38,2<=$G38),$D38,"") | M38: =IF(AND(3>=$F38,3<=$G38),$D38,"") | N38: =IF(AND(4>=$F38,4<=$G38),$D38,"") | O38: =IF(AND(5>=$F38,5<=$G38),$D38,"") | P38: =IF(AND(6>=$F38,6<=$G38),$D38,"") | Q38: =IF(AND(7>=$F38,7<=$G38),$D38,"")
A39: 5.2 | B39: Update Model, scenarios, Dashboard | C39: Dashboard final; numbers frozen | D39: M3 | F39: 4 | G39: 4 | H39: 3 | I39: 5.1 | J39: Not started | K39: =IF(AND(1>=$F39,1<=$G39),$D39,"") | L39: =IF(AND(2>=$F39,2<=$G39),$D39,"") | M39: =IF(AND(3>=$F39,3<=$G39),$D39,"") | N39: =IF(AND(4>=$F39,4<=$G39),$D39,"") | O39: =IF(AND(5>=$F39,5<=$G39),$D39,"") | P39: =IF(AND(6>=$F39,6<=$G39),$D39,"") | Q39: =IF(AND(7>=$F39,7<=$G39),$D39,"")
A40: 5.3 | B40: Re-run run_tests.py with final assumptions | C40: Simulation tab refreshed | D40: M3 | F40: 5 | G40: 5 | H40: 2 | I40: 5.2 | J40: Not started | K40: =IF(AND(1>=$F40,1<=$G40),$D40,"") | L40: =IF(AND(2>=$F40,2<=$G40),$D40,"") | M40: =IF(AND(3>=$F40,3<=$G40),$D40,"") | N40: =IF(AND(4>=$F40,4<=$G40),$D40,"") | O40: =IF(AND(5>=$F40,5<=$G40),$D40,"") | P40: =IF(AND(6>=$F40,6<=$G40),$D40,"") | Q40: =IF(AND(7>=$F40,7<=$G40),$D40,"")
A41: 5.4 | B41: Finalize KPI tree (outcome + driver KPIs) | C41: KPI slide | D41: M3 | E41: M2 | F41: 5 | G41: 6 | H41: 2 | I41: 5.2 | J41: Not started | K41: =IF(AND(1>=$F41,1<=$G41),$D41,"") | L41: =IF(AND(2>=$F41,2<=$G41),$D41,"") | M41: =IF(AND(3>=$F41,3<=$G41),$D41,"") | N41: =IF(AND(4>=$F41,4<=$G41),$D41,"") | O41: =IF(AND(5>=$F41,5<=$G41),$D41,"") | P41: =IF(AND(6>=$F41,6<=$G41),$D41,"") | Q41: =IF(AND(7>=$F41,7<=$G41),$D41,"")
A42: 5.5 | B42: Non-financial impact: time, flexibility, capability | C42: Impact summary slide | D42: M3 | E42: M1 | F42: 5 | G42: 6 | H42: 2 | I42: 4.2 | J42: Not started | K42: =IF(AND(1>=$F42,1<=$G42),$D42,"") | L42: =IF(AND(2>=$F42,2<=$G42),$D42,"") | M42: =IF(AND(3>=$F42,3<=$G42),$D42,"") | N42: =IF(AND(4>=$F42,4<=$G42),$D42,"") | O42: =IF(AND(5>=$F42,5<=$G42),$D42,"") | P42: =IF(AND(6>=$F42,6<=$G42),$D42,"") | Q42: =IF(AND(7>=$F42,7<=$G42),$D42,"")
A43: 6 | B43: DECK & STORY | F43: 0 | G43: 0
...

Sheet Answer_Guide
A1: How to answer each sub-question
A3: Section | B3: What judges look for | C3: How to answer (steps) | D3: Data to use | E3: Model tab | F3: Traps to avoid
A4: Executive summary (1 slide) | B4: One clear answer in 30 seconds: the idea, why now, impact, investment, ask. | C4: Write it LAST but draft it on Day 3. Situation (cost index 106 vs 89, multi-pathway coming) -> Complication (open loops in quality, data, knowledge) -> Answer (your one system) -> Impact (NPV, index, months) -> Roadmap headline. | D4: Exhibit 3, Dashboard | E4: Dashboard | F4: Listing 5 ideas; burying the number; no single name for the idea.
A5: SQ1. Future manufacturing vision & biggest gaps | B5: A vivid 2030 picture that goes BEYOND lower cost, and a prioritized, evidence-based gap. | C5: 1) Write a 2030 vision statement (people + technology + flexibility). 2) Define 'new value' beyond cost: speed to launch variants, knowledge that compounds, engaged people. 3) Build a gap heat map: process (Exhibit 5) x impact on cost & quality (Exhibit 4). 4) Show the gap is BETWEEN processes (integration, data, feedback). 5) Pick 1-2 priority gaps. | D5: Exhibits 3, 4, 5, 8 | E5: Exhibits | F5: Vision that is just a list of technologies; ignoring that the case says the gap lies between processes.
A6: SQ2. Transformative idea | B6: How manufacturing itself changes; people stay at the center; mindset shift; know-how becomes shared knowledge. | C6: 1) Name the idea and show ONE system diagram. 2) Walk through a 'day in the life' of an operator and an engineer before vs after. 3) Explain the mindset shift (operate & maintain -> improve & transform) and the mechanism that drives it (time freed, idea channel, recognition). 4) Show how know-how is captured, validated, reused. 5) Explain in-house vs partner logic. 6) Anchor every element in a TPS principle. | D6: Exhibits 6A, 6B, 7; Ideation tab | E6: Ideation | F6: Recommending a product/device; AI replacing people; no answer to the 31% who override alerts.
A7: SQ3. Roadmap & capability building | B7: Credible phasing 2026-2030 with pilot, standardization, rollout, talent, partners, risks. | C7: 1) Phase 0 (Q4 2026): build on AI camera validation; choose pilot area; set data standard. 2) Pilot (2027) with go/no-go KPIs. 3) Standardize (2028). 4) Roll out (2029-30). 5) Talent: tiered academy moving engineers up Exhibit 7 levels, operator data training. 6) Partners only where they add distinctive value. 7) Risk register with mitigations. | D7: Exhibits 5, 6A, 7; Roadmap tab | E7: Roadmap, KPIs | F7: Everything starting in year 1; no gate criteria; no owner; ignoring training (18% trained).
A8: SQ4. Competitive & financial impact | B8: Impact on cost, quality, time, flexibility, capability; investment; KPIs. Numbers must be traceable. | C8: 1) Bottom-up savings by lever (Model tab). 2) Investment inside Rp40-120B. 3) NPV at 10%, payback, IRR, 3 scenarios. 4) Break-even framing (Breakeven tab). 5) Translate to cost index vs benchmark. 6) Non-financial impact: months per variant, ramp-up time, ideas, skills. 7) KPI tree with baselines and targets. | D8: Exhibit 9, 3, 4; Model, Dashboard, Breakeven, KPIs | E8: Model, Dashboard | F8: Claiming 100% of the gap; ignoring running and training cost; no sensitivity; unlabeled assumptions.
A9: Q&A preparation | B9: Calm, data-backed answers; shows the team owns the logic. | C9: Prepare answers for: Why this pilot area? What if operators resist? Why in-house, not buy? What if the AI camera fails validation? How do you avoid job losses? What happens in the aggressive BEV scenario? Which assumption hurts NPV most? How does this differ from what Toyota Japan already does? | D9: All | E9: Breakeven (sensitivity) | F9: One person answering everything; arguing with judges.
A12: Suggested deck storyline (fill [ ] with your numbers; titles must read as a story on their own)
A13: # | B13: Slide | C13: Example action title / content | D13: Owner
A14: 1 | B14: Title | C14: Idea name + one-line promise | D14: M1
A15: 2 | B15: Executive summary | C15: TMMIN can close [x]% of its cost gap and cut variant changeover from 9 to [x] months by making the plant learn from itself | D15: M1
A16: 3 | B16: Situation | C16: Market fell 7% while new players run [~19]% cheaper per unit | D16: M1
A17: 4 | B17: Complication | C17: Multi-pathway mix lifts electrified share to [55-70]% by 2030, but every variant still costs ~9 months of rework | D17: M1
A18: 5 | B18: Root cause | C18: The real gap sits between processes: quality, data and know-how loops are open | D18: M2
A19: 6 | B19: 2030 vision (SQ1) | C19: In 2030 TMMIN's advantage is a production system that learns, not one that is bought | D19: M1
A20: 7 | B20: Gap prioritization (SQ1) | C20: [Pilot area] is where the open loops cost the most | D20: M2
A21: 8 | B21: The idea (SQ2) | C21: [Idea name]: three closed loops with people at the center | D21: M2
A22: 9 | B22: How it works (SQ2) | C22: A day in the life: operator and engineer before vs after | D22: M2
A23: 10 | B23: Mindset & knowledge (SQ2) | C23: Engineers move from firefighting to improving, and know-how leaves the heads of a few experts | D23: M1
A24: 11 | B24: In-house vs partners (SQ2/3) | C24: Build what differentiates, partner where partners add distinctive value | D24: M2
... A31: App. | B31: Appendix | C31: Assumptions list, sensitivity, alternatives considered (Ideation), exhibit re-type, methodology | D31: M3

Sheet Ideation
A1: Idea options: generate, compare, then combine into ONE system
A2: Case rule: the answer must change HOW manufacturing works (process, ways of working, people, knowledge), not recommend a product or machine.
A4: # | B4: Idea | C4: How manufacturing changes | D4: Case gaps it closes | E4: TPS anchor | F4: Public Toyota precedent | G4: Strength | H4: Risk / weakness | I4: References & evidence (cite in deck)
A5: A | B5: Closed-Loop Jidoka ("Self-Healing Line") | C5: Every abnormality detected anywhere (AI inspection, sensors, operator) is routed automatically to the upstream process that caused it, with a clear stop / correct / escalate rule. Operators confirm and fix; the line learns. | D5: Inspection L1, sealer with no feedback, defects found late, scrap up, 31% override alerts | E5: Jidoka, andon, built-in quality | F5: Toyota Japan uses worker-built AI models for adhesive-application inspection | G5: Strong cost + quality story; uses the Oct 2026 AI camera as a building block | H5: Needs data integration first; alert fatigue if poorly designed | I5: Google Cloud (2024) Toyota AI Platform: https://cloud.google.com/blog/topics/hybrid-cloud/toyota-ai-platform-manufacturing-efficiency DigitalDefynd (2026) 10 ways Toyota uses AI: https://digitaldefynd.com/IQ/toyota-using-ai-case-study/ The Future Factory (2026) TPS in the age of AI: https://www.thefuturefactory.com/insights/toyota-production-system-age-of-ai Own test: Simulation tab (closed-loop quality sim + Monte Carlo)
A6: B | B6: Plug-and-Produce Plant Standard (in-house) | C6: TMMIN defines one common interface + data standard; every new or modified equipment plugs into it. In-house engineers build standard equipment and apps on top. Variant change becomes configuration, not rewiring. | D6: Point-to-point integration, 9-month modification, scattered data, costly closed external tech | E6: Standardized work applied to equipment; heijunka for mixed models | F6: Toyota insources equipment tech (self-propelled conveyance at Motomachi) | G6: Direct answer to multi-pathway flexibility and in-house capability | H6: Less emotional / people story on its own; standard-setting takes discipline | I6: Toyota (2023) Monozukuri tech, in-house self-propelled conveyance: https://global.toyota/en/newsroom/corporate/39758451.html Toyota (2023) BEV production process, halve prep lead time & investment: https://global.toyota/en/newsroom/corporate/39330500.html Case: point-to-point integration, 9-month modification (Exhibits 4, 5)
A7: C | B7: Citizen Kaizen AI Platform | C7: Team leaders and operators build simple AI / data tools themselves through a no-code platform, plus an easy idea channel with fast engineer support. Engineers become coaches and platform owners. | D7: Ideas down 3.1->2.4, implementation 35%->28%, 62% would contribute with an easy channel, 18% trained | E7: Kaizen, respect for people | F7: Toyota AI Platform: ~10,000 models built by factory staff, ~1,200 active users | G7: Most human-centered; scales kaizen; very Toyota | H7: Needs governance (model quality, safety); training load | I7: Google Cloud (2024) Toyota AI Platform: https://cloud.google.com/blog/topics/hybrid-cloud/toyota-ai-platform-manufacturing-efficiency Chief AI Officer (2025) 10,000 models / 10,000 hrs: https://chiefaiofficer.com/blog/how-toyota-gave-ai-tools-to-factory-workers-and-saved-10000-hours/ Case Exhibit 6B: 62% would contribute ideas with an easy channel
A8: D | B8: Shop-Floor O-Beya ("Digital Sensei") | C8: Capture senior experts' troubleshooting and process know-how into shared standards and an AI assistant that new engineers and team leaders consult. Experts validate content; it becomes living standard work. | D8: Know-how with 1-2 seniors, low documentation, 15-month ramp-up, engineers stuck firefighting | E8: Yokoten (horizontal deployment), standardized work, hansei | F8: Toyota O-Beya: 9 AI agents for ~800 powertrain engineers | G8: Cheap, fast to pilot, addresses knowledge and talent directly | H8: Weaker direct cost impact; content quality depends on seniors' time | I8: Microsoft Source Asia (2024) O-Beya: https://news.microsoft.com/source/asia/features/toyota-is-deploying-ai-agents-to-harness-the-collective-wisdom-of-engineers-and-innovate-faster/ ABI Research (2025) O-Beya knowledge mgmt: https://www.abiresearch.com/market-research/insight/7786905-toyotas-o-beya-provides-best-practices-for Aicadium (2026) Lean to AI, GAIA + 100-course academy: https://aicadium.ai/lean-to-ai-what-toyotas-transformation-looks-like-today/ Case Exhibit 6A: know-how with 1-2 seniors, 15-month ramp-up
A9: E | B9: Simulation-First Production Preparation | C9: Every new variant / pathway is designed, balanced and debugged in a digital model of the line before physical change. Engineers own the models. | D9: 9-month modification, multi-pathway mix uncertainty (Exhibit 8) | E9: Genchi genbutsu supported by virtual verification; PDCA | F9: Toyota digital process verification for next-gen BEV plants (aim: halve prep lead time) | G9: Strong flexibility + time-to-market story; fits IE skills | H9: Needs reliable data; model upkeep cost | I9: Toyota (2023) BEV production process, halve prep lead time & investment: https://global.toyota/en/newsroom/corporate/39330500.html Case Exhibit 8: electrified share 30% -> 55-70%
A10: F | B10: Conveyor-Light Flexible Line + Synchronized Intralogistics | C10: Redesign flow around mobile automation (AMR/AGV, self-propelled concepts) so layout and sequence adapt to the variant mix; material flow synced with production signals. | D10: Manual forklifts/dollies, flow not synchronized, NVA 22% | E10: JIT, kanban, heijunka | F10: Toyota self-propelled assembly line trials | G10: Big flexibility upside, visually impressive | H10: Capex heavy, risks reading as equipment recommendation | I10: Assembly Magazine (2023) self-propelled lines: https://www.assemblymag.com/articles/98199-toyota-outlines-future-production-processes Toyota (2023) Monozukuri tech, in-house self-propelled conveyance: https://global.toyota/en/newsroom/corporate/39758451.html
A11: G | B11: AI-Enabled Autonomous Maintenance (TPM 2.0) | C11: Operators and maintenance jointly own equipment health using condition data; predictive alerts with operator-led first response. | D11: Periodic preventive only, rising unplanned downtime | E11: TPM, jidoka | F11: Toyota AI Platform used for injection-moulding abnormality detection | G11: Clear downtime savings, practical | H11: Narrower scope; many competitors will propose it | I11: Google Cloud (2024) Toyota AI Platform: https://cloud.google.com/blog/topics/hybrid-cloud/toyota-ai-platform-manufacturing-efficiency Logistics Viewpoints (2025) People + AI: https://logisticsviewpoints.com/2025/06/05/people-ai-augmenting-the-supply-chain-workforce/
A12: H | B12: INTEGRATED: Closed-Loop Production System (A+B+C+D) | C12: One operating system with three loops: quality loop (A), data/equipment loop (B), people & knowledge loop (C+D). Piloted in one area, standardized, then rolled out plant-wide. | D12: Attacks all three complications at once | E12: Jidoka + kaizen + standardization, in the digital era | F12: Combines the Toyota precedents above | G12: Best answer to 'system not product'; one memorable idea | H12: Complex to explain: needs one clean diagram and one pilot | I12: Google Cloud (2024) Toyota AI Platform: https://cloud.google.com/blog/topics/hybrid-cloud/toyota-ai-platform-manufacturing-efficiency Microsoft Source Asia (2024) O-Beya: https://news.microsoft.com/source/asia/features/toyota-is-deploying-ai-agents-to-harness-the-collective-wisdom-of-engineers-and-innovate-faster/ Toyota (2023) Monozukuri tech, in-house self-propelled conveyance: https://global.toyota/en/newsroom/corporate/39758451.html Aicadium (2026) Lean to AI, GAIA + 100-course academy: https://aicadium.ai/lean-to-ai-what-toyotas-transformation-looks-like-today/ Own test: Simulation tab (closed-loop quality sim + Monte Carlo)
A15: Scoring matrix (scores 1-5 are suggestions: re-score as a team on Day 3)
A16: # | B16: Idea | C16: Cost & quality impact | D16: Multi-pathway flexibility | E16: People at the center / knowledge | F16: Hard to buy off the shelf (in-house value) | G16: Feasible in Rp40-120B by 2030 | H16: Fits case ask: system, not product | I16: Weighted score | J16: Rank
B17: Weight | C17: 0.25 | D17: 0.15 | E17: 0.2 | F17: 0.15 | G17: 0.15 | H17: 0.1 | I17: =SUM(C17:H17)
A18: A | B18: Closed-Loop Jidoka ("Self-Healing Line") | C18: 5 | D18: 3 | E18: 4 | F18: 4 | G18: 4 | H18: 5 | I18: =SUMPRODUCT($C$17:$H$17,C18:H18) | J18: =RANK(I18,$I$18:$I$25)
A19: B | B19: Plug-and-Produce Plant Standard (in-house) | C19: 3 | D19: 5 | E19: 3 | F19: 5 | G19: 3 | H19: 5 | I19: =SUMPRODUCT($C$17:$H$17,C19:H19) | J19: =RANK(I19,$I$18:$I$25)
A20: C | B20: Citizen Kaizen AI Platform | C20: 4 | D20: 3 | E20: 5 | F20: 5 | G20: 4 | H20: 4 | I20: =SUMPRODUCT($C$17:$H$17,C20:H20) | J20: =RANK(I20,$I$18:$I$25)
A21: D | B21: Shop-Floor O-Beya ("Digital Sensei") | C21: 2 | D21: 3 | E21: 5 | F21: 4 | G21: 5 | H21: 4 | I21: =SUMPRODUCT($C$17:$H$17,C21:H21) | J21: =RANK(I21,$I$18:$I$25)
A22: E | B22: Simulation-First Production Preparation | C22: 3 | D22: 5 | E22: 3 | F22: 4 | G22: 4 | H22: 4 | I22: =SUMPRODUCT($C$17:$H$17,C22:H22) | J22: =RANK(I22,$I$18:$I$25)
A23: F | B23: Conveyor-Light Flexible Line + Synchronized Intralogistics | C23: 3 | D23: 5 | E23: 2 | F23: 2 | G23: 2 | H23: 2 | I23: =SUMPRODUCT($C$17:$H$17,C23:H23) | J23: =RANK(I23,$I$18:$I$25)
A24: G | B24: AI-Enabled Autonomous Maintenance (TPM 2.0) | C24: 4 | D24: 2 | E24: 4 | F24: 3 | G24: 4 | H24: 3 | I24: =SUMPRODUCT($C$17:$H$17,C24:H24) | J24: =RANK(I24,$I$18:$I$25)
A25: H | B25: INTEGRATED: Closed-Loop Production System (A+B+C+D) | C25: 5 | D25: 4 | E25: 5 | F25: 5 | G25: 3 | H25: 5 | I25: =SUMPRODUCT($C$17:$H$17,C25:H25) | J25: =RANK(I25,$I$18:$I$25)
A27: Tip: the winning pitch is usually one integrated idea (like H) explained through one pilot. Use the lower-ranked options as 'considered and rejected' in the appendix to show rigor.

Sheet Simulation9
A1: Idea tests: simulation results (values produced by run_tests.py, not formulas)
A2: Re-run run_tests.py after changing assumptions. Process parameters below are illustrative assumptions, not TMMIN data: present them as a mechanism test, and show the sensitivity.
A4: TEST 1. Does closing the quality loop beat adding technology alone? (sealer drift -> inspection -> feedback, 1 year, 175,000 units, 300 runs)
A5: Scenario | B5: Defective units / yr | C5: Scrapped units / yr | D5: Escaped defects / yr | E5: Units built while drifting | F5: Scrap vs today | G5: Escapes vs today | H5: Scrap P5-P95
A6: 1. Today: visual at final inspection, manual feedback | B6: 4266.68 | C6: 1088.524 | D6: 638.26667 | E6: 15796.093 | F6: 0 | G6: 0 | H6: 835 - 1,365
A7: 2. Better camera at end-of-line only (tech, no loop) | B7: 4265.3233 | C7: 1215.776 | D7: 212.73667 | E7: 15793.257 | F7: 0.11690326 | G7: -0.66669626 | H7: 910 - 1,492
A8: 3. Closed loop at sealer, 31% of alerts dismissed (as today) | B8: 1652.95 | C8: 362.15367 | D8: 203.26 | E8: 5247.72 | F8: -0.66729841 | G8: -0.68154376 | H8: 216 - 543
A9: 4. Closed loop with people-centred design (10% dismissed) | B9: 908.32333 | C9: 166.86333 | D9: 88.006667 | E9: 2257.0067 | F9: -0.84670679 | G9: -0.86211615 | H9: 83 - 270
A11: What this shows
A12: - A better camera at end-of-line alone changes scrap by +12% while escapes fall 67%: it catches more bad units, but too late, so escapes turn into scrap. It does not prevent defects.
A13: - Closing the loop right after the sealer cuts scrap 85% and escapes 86%, because a drift is stopped within a few units instead of hundreds.
A14: - If operators dismiss alerts in 31% of drift episodes (today's override rate), scrap reduction falls to 67%. Trust, training and alert design are part of the value, not an add-on.
A15: - Plant-wide: if the pilot scope causes 40% of plant scrap (team assumption), the plant-wide scrap cut is about 34%. Compare with the 20% / 35% / 50% lever in Assumptions.
A16: - Deck message: value comes from redesigning the system (where the check sits, how fast the signal travels, who acts on it), not from buying the device. That is exactly the case ask.
A18: Process assumptions used (illustrative, change and re-run)
A19: Defect probability per unit, stable sealer | B19: 0.002
A20: Average units between drift events | B20: 5000
A21: Defect probability per unit while drifting | B21: 0.25
A22: Manual visual detection rate at final inspection | B22: 0.85
A23: Share of sealer defect modes the in-line AI camera can see | B23: 0.7
A24: Units between sealer and today's final inspection | B24: 300
A25: Units built before manual feedback reaches the sealer | B25: 150
A26: Share of late-found defects scrapped | B26: 0.3
A27: Share of early-found defects scrapped | B27: 0.05
A28: Share of plant scrap from the pilot scope (team assumption) | B28: 0.4
A29: In-line check: 5 units after sealer, automatic feedback within 10 units, 90% detection on visible defect modes (case: AI camera in validation to Oct 2026).
A31: Robustness: closed-loop (scenario 4) scrap reduction vs today when each assumption changes
A32: Assumption | B32: Low | C32: Reduction | D32: Base | E32: Reduction | F32: High | G32: Reduction
A33: AI camera coverage of defect modes | B33: 0.5 | C33: 0.8247043 | D33: 0.7 | E33: 0.84684226 | F33: 0.9 | G33: 0.86670882
A34: Drift defect rate | B34: 0.1 | C34: 0.8026018 | D34: 0.25 | E34: 0.84799063 | F34: 0.4 | G34: 0.86492434
A35: Units between drift events | B35: 2500 | C35: 0.86340745 | D35: 5000 | E35: 0.85825104 | F35: 10000 | G35: 0.83368165
A36: Late-found scrap share | B36: 0.15 | C36: 0.83146269 | D36: 0.3 | E36: 0.85387796 | F36: 0.5 | G36: 0.85017711
A37: Units from sealer to today's inspection | B37: 100 | C37: 0.81112305 | D37: 300 | E37: 0.8492534 | F37: 600 | G37: 0.87379761
A38: Lowest scrap reduction across all tested cases: 80%. The mechanism holds even with pessimistic process assumptions.
A40: People test: how much value is lost when operators dismiss alerts?
A41: Share of drift episodes where alerts are dismissed | B41: Scrap reduction vs today
A42: 0 | B42: 0.93929302
A43: 0.1 | B43: 0.84457608
A44: 0.2 | B44: 0.7497195
A45: 0.31 | B45: 0.64310602
...

Sheet Simulation8
A1: Idea tests: simulation results (values produced by run_tests.py, not formulas)
A2: Re-run run_tests.py after changing assumptions. Process parameters below are illustrative assumptions, not TMMIN data: present them as a mechanism test, and show the sensitivity.
A4: TEST 1. Does closing the quality loop beat adding technology alone? (sealer drift -> inspection -> feedback, 1 year, 175,000 units, 300 runs)
A5: Scenario | B5: Defective units / yr | C5: Scrapped units / yr | D5: Escaped defects / yr | E5: Units built while drifting | F5: Scrap vs today | G5: Escapes vs today | H5: Scrap P5-P95
A6: 1. Today: visual at final inspection, manual feedback | B6: 4266.68 | C6: 1088.524 | D6: 638.26667 | E6: 15796.093 | F6: 0 | G6: 0 | H6: 835 - 1,365
A7: 2. Better camera at end-of-line only (tech, no loop) | B7: 4265.3233 | C7: 1215.776 | D7: 212.73667 | E7: 15793.257 | F7: 0.11690326 | G7: -0.66669626 | H7: 910 - 1,492
A8: 3. Closed loop at sealer, 31% of alerts dismissed (as today) | B8: 1652.95 | C8: 362.15367 | D8: 203.26 | E8: 5247.72 | F8: -0.66729841 | G8: -0.68154376 | H8: 216 - 543
A9: 4. Closed loop with people-centred design (10% dismissed) | B9: 908.32333 | C9: 166.86333 | D9: 88.006667 | E9: 2257.0067 | F9: -0.84670679 | G9: -0.86211615 | H9: 83 - 270
A11: What this shows
A12: - A better camera at end-of-line alone changes scrap by +12% while escapes fall 67%: it catches more bad units, but too late, so escapes turn into scrap. It does not prevent defects.
A13: - Closing the loop right after the sealer cuts scrap 85% and escapes 86%, because a drift is stopped within a few units instead of hundreds.
A14: - If operators dismiss alerts in 31% of drift episodes (today's override rate), scrap reduction falls to 67%. Trust, training and alert design are part of the value, not an add-on.
A15: - Plant-wide: if the pilot scope causes 40% of plant scrap (team assumption), the plant-wide scrap cut is about 34%. Compare with the 20% / 35% / 50% lever in Assumptions.
A16: - Deck message: value comes from redesigning the system (where the check sits, how fast the signal travels, who acts on it), not from buying the device. That is exactly the case ask.
A18: Process assumptions used (illustrative, change and re-run)
A19: Defect probability per unit, stable sealer | B19: 0.002
A20: Average units between drift events | B20: 5000
A21: Defect probability per unit while drifting | B21: 0.25
A22: Manual visual detection rate at final inspection | B22: 0.85
A23: Share of sealer defect modes the in-line AI camera can see | B23: 0.7
A24: Units between sealer and today's final inspection | B24: 300
A25: Units built before manual feedback reaches the sealer | B25: 150
A26: Share of late-found defects scrapped | B26: 0.3
A27: Share of early-found defects scrapped | B27: 0.05
A28: Share of plant scrap from the pilot scope (team assumption) | B28: 0.4
A29: In-line check: 5 units after sealer, automatic feedback within 10 units, 90% detection on visible defect modes (case: AI camera in validation to Oct 2026).
A31: Robustness: closed-loop (scenario 4) scrap reduction vs today when each assumption changes
A32: Assumption | B32: Low | C32: Reduction | D32: Base | E32: Reduction | F32: High | G32: Reduction
A33: AI camera coverage of defect modes | B33: 0.5 | C33: 0.8247043 | D33: 0.7 | E33: 0.84684226 | F33: 0.9 | G33: 0.86670882
A34: Drift defect rate | B34: 0.1 | C34: 0.8026018 | D34: 0.25 | E34: 0.84799063 | F34: 0.4 | G34: 0.86492434
A35: Units between drift events | B35: 2500 | C35: 0.86340745 | D35: 5000 | E35: 0.85825104 | F35: 10000 | G35: 0.83368165
A36: Late-found scrap share | B36: 0.15 | C36: 0.83146269 | D36: 0.3 | E36: 0.85387796 | F36: 0.5 | G36: 0.85017711
A37: Units from sealer to today's inspection | B37: 100 | C37: 0.81112305 | D37: 300 | E37: 0.8492534 | F37: 600 | G37: 0.87379761
A38: Lowest scrap reduction across all tested cases: 80%. The mechanism holds even with pessimistic process assumptions.
A40: People test: how much value is lost when operators dismiss alerts?
A41: Share of drift episodes where alerts are dismissed | B41: Scrap reduction vs today
A42: 0 | B42: 0.93929302
A43: 0.1 | B43: 0.84457608
A44: 0.2 | B44: 0.7497195
A45: 0.31 | B45: 0.64310602
...

Sheet Simulation7
A1: Idea tests: simulation results (values produced by run_tests.py, not formulas)
A2: Re-run run_tests.py after changing assumptions. Process parameters below are illustrative assumptions, not TMMIN data: present them as a mechanism test, and show the sensitivity.
A4: TEST 1. Does closing the quality loop beat adding technology alone? (sealer drift -> inspection -> feedback, 1 year, 175,000 units, 300 runs)
A5: Scenario | B5: Defective units / yr | C5: Scrapped units / yr | D5: Escaped defects / yr | E5: Units built while drifting | F5: Scrap vs today | G5: Escapes vs today | H5: Scrap P5-P95
A6: 1. Today: visual at final inspection, manual feedback | B6: 4266.68 | C6: 1088.524 | D6: 638.26667 | E6: 15796.093 | F6: 0 | G6: 0 | H6: 835 - 1,365
A7: 2. Better camera at end-of-line only (tech, no loop) | B7: 4265.3233 | C7: 1215.776 | D7: 212.73667 | E7: 15793.257 | F7: 0.11690326 | G7: -0.66669626 | H7: 910 - 1,492
A8: 3. Closed loop at sealer, 31% of alerts dismissed (as today) | B8: 1652.95 | C8: 362.15367 | D8: 203.26 | E8: 5247.72 | F8: -0.66729841 | G8: -0.68154376 | H8: 216 - 543
A9: 4. Closed loop with people-centred design (10% dismissed) | B9: 908.32333 | C9: 166.86333 | D9: 88.006667 | E9: 2257.0067 | F9: -0.84670679 | G9: -0.86211615 | H9: 83 - 270
A11: What this shows
A12: - A better camera at end-of-line alone changes scrap by +12% while escapes fall 67%: it catches more bad units, but too late, so escapes turn into scrap. It does not prevent defects.
A13: - Closing the loop right after the sealer cuts scrap 85% and escapes 86%, because a drift is stopped within a few units instead of hundreds.
A14: - If operators dismiss alerts in 31% of drift episodes (today's override rate), scrap reduction falls to 67%. Trust, training and alert design are part of the value, not an add-on.
A15: - Plant-wide: if the pilot scope causes 40% of plant scrap (team assumption), the plant-wide scrap cut is about 34%. Compare with the 20% / 35% / 50% lever in Assumptions.
A16: - Deck message: value comes from redesigning the system (where the check sits, how fast the signal travels, who acts on it), not from buying the device. That is exactly the case ask.
A18: Process assumptions used (illustrative, change and re-run)
A19: Defect probability per unit, stable sealer | B19: 0.002
A20: Average units between drift events | B20: 5000
A21: Defect probability per unit while drifting | B21: 0.25
A22: Manual visual detection rate at final inspection | B22: 0.85
A23: Share of sealer defect modes the in-line AI camera can see | B23: 0.7
A24: Units between sealer and today's final inspection | B24: 300
A25: Units built before manual feedback reaches the sealer | B25: 150
A26: Share of late-found defects scrapped | B26: 0.3
A27: Share of early-found defects scrapped | B27: 0.05
A28: Share of plant scrap from the pilot scope (team assumption) | B28: 0.4
A29: In-line check: 5 units after sealer, automatic feedback within 10 units, 90% detection on visible defect modes (case: AI camera in validation to Oct 2026).
A31: Robustness: closed-loop (scenario 4) scrap reduction vs today when each assumption changes
A32: Assumption | B32: Low | C32: Reduction | D32: Base | E32: Reduction | F32: High | G32: Reduction
A33: AI camera coverage of defect modes | B33: 0.5 | C33: 0.8247043 | D33: 0.7 | E33: 0.84684226 | F33: 0.9 | G33: 0.86670882
A34: Drift defect rate | B34: 0.1 | C34: 0.8026018 | D34: 0.25 | E34: 0.84799063 | F34: 0.4 | G34: 0.86492434
A35: Units between drift events | B35: 2500 | C35: 0.86340745 | D35: 5000 | E35: 0.85825104 | F35: 10000 | G35: 0.83368165
A36: Late-found scrap share | B36: 0.15 | C36: 0.83146269 | D36: 0.3 | E36: 0.85387796 | F36: 0.5 | G36: 0.85017711
A37: Units from sealer to today's inspection | B37: 100 | C37: 0.81112305 | D37: 300 | E37: 0.8492534 | F37: 600 | G37: 0.87379761
A38: Lowest scrap reduction across all tested cases: 80%. The mechanism holds even with pessimistic process assumptions.
A40: People test: how much value is lost when operators dismiss alerts?
A41: Share of drift episodes where alerts are dismissed | B41: Scrap reduction vs today
A42: 0 | B42: 0.93929302
A43: 0.1 | B43: 0.84457608
A44: 0.2 | B44: 0.7497195
A45: 0.31 | B45: 0.64310602
...

Sheet Simulation6
A1: Idea tests: simulation results (values produced by run_tests.py, not formulas)
A2: Re-run run_tests.py after changing assumptions. Process parameters below are illustrative assumptions, not TMMIN data: present them as a mechanism test, and show the sensitivity.
A4: TEST 1. Does closing the quality loop beat adding technology alone? (sealer drift -> inspection -> feedback, 1 year, 175,000 units, 300 runs)
A5: Scenario | B5: Defective units / yr | C5: Scrapped units / yr | D5: Escaped defects / yr | E5: Units built while drifting | F5: Scrap vs today | G5: Escapes vs today | H5: Scrap P5-P95
A6: 1. Today: visual at final inspection, manual feedback | B6: 4266.68 | C6: 1088.524 | D6: 638.26667 | E6: 15796.093 | F6: 0 | G6: 0 | H6: 835 - 1,365
A7: 2. Better camera at end-of-line only (tech, no loop) | B7: 4265.3233 | C7: 1215.776 | D7: 212.73667 | E7: 15793.257 | F7: 0.11690326 | G7: -0.66669626 | H7: 910 - 1,492
A8: 3. Closed loop at sealer, 31% of alerts dismissed (as today) | B8: 1652.95 | C8: 362.15367 | D8: 203.26 | E8: 5247.72 | F8: -0.66729841 | G8: -0.68154376 | H8: 216 - 543
A9: 4. Closed loop with people-centred design (10% dismissed) | B9: 908.32333 | C9: 166.86333 | D9: 88.006667 | E9: 2257.0067 | F9: -0.84670679 | G9: -0.86211615 | H9: 83 - 270
A11: What this shows
A12: - A better camera at end-of-line alone changes scrap by +12% while escapes fall 67%: it catches more bad units, but too late, so escapes turn into scrap. It does not prevent defects.
A13: - Closing the loop right after the sealer cuts scrap 85% and escapes 86%, because a drift is stopped within a few units instead of hundreds.
A14: - If operators dismiss alerts in 31% of drift episodes (today's override rate), scrap reduction falls to 67%. Trust, training and alert design are part of the value, not an add-on.
A15: - Plant-wide: if the pilot scope causes 40% of plant scrap (team assumption), the plant-wide scrap cut is about 34%. Compare with the 20% / 35% / 50% lever in Assumptions.
A16: - Deck message: value comes from redesigning the system (where the check sits, how fast the signal travels, who acts on it), not from buying the device. That is exactly the case ask.
A18: Process assumptions used (illustrative, change and re-run)
A19: Defect probability per unit, stable sealer | B19: 0.002
A20: Average units between drift events | B20: 5000
A21: Defect probability per unit while drifting | B21: 0.25
A22: Manual visual detection rate at final inspection | B22: 0.85
A23: Share of sealer defect modes the in-line AI camera can see | B23: 0.7
A24: Units between sealer and today's final inspection | B24: 300
A25: Units built before manual feedback reaches the sealer | B25: 150
A26: Share of late-found defects scrapped | B26: 0.3
A27: Share of early-found defects scrapped | B27: 0.05
A28: Share of plant scrap from the pilot scope (team assumption) | B28: 0.4
A29: In-line check: 5 units after sealer, automatic feedback within 10 units, 90% detection on visible defect modes (case: AI camera in validation to Oct 2026).
A31: Robustness: closed-loop (scenario 4) scrap reduction vs today when each assumption changes
A32: Assumption | B32: Low | C32: Reduction | D32: Base | E32: Reduction | F32: High | G32: Reduction
A33: AI camera coverage of defect modes | B33: 0.5 | C33: 0.8247043 | D33: 0.7 | E33: 0.84684226 | F33: 0.9 | G33: 0.86670882
A34: Drift defect rate | B34: 0.1 | C34: 0.8026018 | D34: 0.25 | E34: 0.84799063 | F34: 0.4 | G34: 0.86492434
A35: Units between drift events | B35: 2500 | C35: 0.86340745 | D35: 5000 | E35: 0.85825104 | F35: 10000 | G35: 0.83368165
A36: Late-found scrap share | B36: 0.15 | C36: 0.83146269 | D36: 0.3 | E36: 0.85387796 | F36: 0.5 | G36: 0.85017711
A37: Units from sealer to today's inspection | B37: 100 | C37: 0.81112305 | D37: 300 | E37: 0.8492534 | F37: 600 | G37: 0.87379761
A38: Lowest scrap reduction across all tested cases: 80%. The mechanism holds even with pessimistic process assumptions.
A40: People test: how much value is lost when operators dismiss alerts?
A41: Share of drift episodes where alerts are dismissed | B41: Scrap reduction vs today
A42: 0 | B42: 0.93929302
A43: 0.1 | B43: 0.84457608
A44: 0.2 | B44: 0.7497195
A45: 0.31 | B45: 0.64310602
...

Sheet Simulation5
A1: Idea tests: simulation results (values produced by run_tests.py, not formulas)
A2: Re-run run_tests.py after changing assumptions. Process parameters below are illustrative assumptions, not TMMIN data: present them as a mechanism test, and show the sensitivity.
A4: TEST 1. Does closing the quality loop beat adding technology alone? (sealer drift -> inspection -> feedback, 1 year, 175,000 units, 300 runs)
A5: Scenario | B5: Defective units / yr | C5: Scrapped units / yr | D5: Escaped defects / yr | E5: Units built while drifting | F5: Scrap vs today | G5: Escapes vs today | H5: Scrap P5-P95
A6: 1. Today: visual at final inspection, manual feedback | B6: 4266.68 | C6: 1088.524 | D6: 638.26667 | E6: 15796.093 | F6: 0 | G6: 0 | H6: 835 - 1,365
A7: 2. Better camera at end-of-line only (tech, no loop) | B7: 4265.3233 | C7: 1215.776 | D7: 212.73667 | E7: 15793.257 | F7: 0.11690326 | G7: -0.66669626 | H7: 910 - 1,492
A8: 3. Closed loop at sealer, 31% of alerts dismissed (as today) | B8: 1652.95 | C8: 362.15367 | D8: 203.26 | E8: 5247.72 | F8: -0.66729841 | G8: -0.68154376 | H8: 216 - 543
A9: 4. Closed loop with people-centred design (10% dismissed) | B9: 908.32333 | C9: 166.86333 | D9: 88.006667 | E9: 2257.0067 | F9: -0.84670679 | G9: -0.86211615 | H9: 83 - 270
A11: What this shows
A12: - A better camera at end-of-line alone changes scrap by +12% while escapes fall 67%: it catches more bad units, but too late, so escapes turn into scrap. It does not prevent defects.
A13: - Closing the loop right after the sealer cuts scrap 85% and escapes 86%, because a drift is stopped within a few units instead of hundreds.
A14: - If operators dismiss alerts in 31% of drift episodes (today's override rate), scrap reduction falls to 67%. Trust, training and alert design are part of the value, not an add-on.
A15: - Plant-wide: if the pilot scope causes 40% of plant scrap (team assumption), the plant-wide scrap cut is about 34%. Compare with the 20% / 35% / 50% lever in Assumptions.
A16: - Deck message: value comes from redesigning the system (where the check sits, how fast the signal travels, who acts on it), not from buying the device. That is exactly the case ask.
A18: Process assumptions used (illustrative, change and re-run)
A19: Defect probability per unit, stable sealer | B19: 0.002
A20: Average units between drift events | B20: 5000
A21: Defect probability per unit while drifting | B21: 0.25
A22: Manual visual detection rate at final inspection | B22: 0.85
A23: Share of sealer defect modes the in-line AI camera can see | B23: 0.7
A24: Units between sealer and today's final inspection | B24: 300
A25: Units built before manual feedback reaches the sealer | B25: 150
A26: Share of late-found defects scrapped | B26: 0.3
A27: Share of early-found defects scrapped | B27: 0.05
A28: Share of plant scrap from the pilot scope (team assumption) | B28: 0.4
A29: In-line check: 5 units after sealer, automatic feedback within 10 units, 90% detection on visible defect modes (case: AI camera in validation to Oct 2026).
A31: Robustness: closed-loop (scenario 4) scrap reduction vs today when each assumption changes
A32: Assumption | B32: Low | C32: Reduction | D32: Base | E32: Reduction | F32: High | G32: Reduction
A33: AI camera coverage of defect modes | B33: 0.5 | C33: 0.8247043 | D33: 0.7 | E33: 0.84684226 | F33: 0.9 | G33: 0.86670882
A34: Drift defect rate | B34: 0.1 | C34: 0.8026018 | D34: 0.25 | E34: 0.84799063 | F34: 0.4 | G34: 0.86492434
A35: Units between drift events | B35: 2500 | C35: 0.86340745 | D35: 5000 | E35: 0.85825104 | F35: 10000 | G35: 0.83368165
A36: Late-found scrap share | B36: 0.15 | C36: 0.83146269 | D36: 0.3 | E36: 0.85387796 | F36: 0.5 | G36: 0.85017711
A37: Units from sealer to today's inspection | B37: 100 | C37: 0.81112305 | D37: 300 | E37: 0.8492534 | F37: 600 | G37: 0.87379761
A38: Lowest scrap reduction across all tested cases: 80%. The mechanism holds even with pessimistic process assumptions.
A40: People test: how much value is lost when operators dismiss alerts?
A41: Share of drift episodes where alerts are dismissed | B41: Scrap reduction vs today
A42: 0 | B42: 0.93929302
A43: 0.1 | B43: 0.84457608
A44: 0.2 | B44: 0.7497195
A45: 0.31 | B45: 0.64310602
...

Sheet Simulation4
A1: Idea tests: simulation results (values produced by run_tests.py, not formulas)
A2: Re-run run_tests.py after changing assumptions. Process parameters below are illustrative assumptions, not TMMIN data: present them as a mechanism test, and show the sensitivity.
A4: TEST 1. Does closing the quality loop beat adding technology alone? (sealer drift -> inspection -> feedback, 1 year, 175,000 units, 300 runs)
A5: Scenario | B5: Defective units / yr | C5: Scrapped units / yr | D5: Escaped defects / yr | E5: Units built while drifting | F5: Scrap vs today | G5: Escapes vs today | H5: Scrap P5-P95
A6: 1. Today: visual at final inspection, manual feedback | B6: 4266.68 | C6: 1088.524 | D6: 638.26667 | E6: 15796.093 | F6: 0 | G6: 0 | H6: 835 - 1,365
A7: 2. Better camera at end-of-line only (tech, no loop) | B7: 4265.3233 | C7: 1215.776 | D7: 212.73667 | E7: 15793.257 | F7: 0.11690326 | G7: -0.66669626 | H7: 910 - 1,492
A8: 3. Closed loop at sealer, 31% of alerts dismissed (as today) | B8: 1652.95 | C8: 362.15367 | D8: 203.26 | E8: 5247.72 | F8: -0.66729841 | G8: -0.68154376 | H8: 216 - 543
A9: 4. Closed loop with people-centred design (10% dismissed) | B9: 908.32333 | C9: 166.86333 | D9: 88.006667 | E9: 2257.0067 | F9: -0.84670679 | G9: -0.86211615 | H9: 83 - 270
A11: What this shows
A12: - A better camera at end-of-line alone changes scrap by +12% while escapes fall 67%: it catches more bad units, but too late, so escapes turn into scrap. It does not prevent defects.
A13: - Closing the loop right after the sealer cuts scrap 85% and escapes 86%, because a drift is stopped within a few units instead of hundreds.
A14: - If operators dismiss alerts in 31% of drift episodes (today's override rate), scrap reduction falls to 67%. Trust, training and alert design are part of the value, not an add-on.
A15: - Plant-wide: if the pilot scope causes 40% of plant scrap (team assumption), the plant-wide scrap cut is about 34%. Compare with the 20% / 35% / 50% lever in Assumptions.
A16: - Deck message: value comes from redesigning the system (where the check sits, how fast the signal travels, who acts on it), not from buying the device. That is exactly the case ask.
A18: Process assumptions used (illustrative, change and re-run)
A19: Defect probability per unit, stable sealer | B19: 0.002
A20: Average units between drift events | B20: 5000
A21: Defect probability per unit while drifting | B21: 0.25
A22: Manual visual detection rate at final inspection | B22: 0.85
A23: Share of sealer defect modes the in-line AI camera can see | B23: 0.7
A24: Units between sealer and today's final inspection | B24: 300
A25: Units built before manual feedback reaches the sealer | B25: 150
A26: Share of late-found defects scrapped | B26: 0.3
A27: Share of early-found defects scrapped | B27: 0.05
A28: Share of plant scrap from the pilot scope (team assumption) | B28: 0.4
A29: In-line check: 5 units after sealer, automatic feedback within 10 units, 90% detection on visible defect modes (case: AI camera in validation to Oct 2026).
A31: Robustness: closed-loop (scenario 4) scrap reduction vs today when each assumption changes
A32: Assumption | B32: Low | C32: Reduction | D32: Base | E32: Reduction | F32: High | G32: Reduction
A33: AI camera coverage of defect modes | B33: 0.5 | C33: 0.8247043 | D33: 0.7 | E33: 0.84684226 | F33: 0.9 | G33: 0.86670882
A34: Drift defect rate | B34: 0.1 | C34: 0.8026018 | D34: 0.25 | E34: 0.84799063 | F34: 0.4 | G34: 0.86492434
A35: Units between drift events | B35: 2500 | C35: 0.86340745 | D35: 5000 | E35: 0.85825104 | F35: 10000 | G35: 0.83368165
A36: Late-found scrap share | B36: 0.15 | C36: 0.83146269 | D36: 0.3 | E36: 0.85387796 | F36: 0.5 | G36: 0.85017711
A37: Units from sealer to today's inspection | B37: 100 | C37: 0.81112305 | D37: 300 | E37: 0.8492534 | F37: 600 | G37: 0.87379761
A38: Lowest scrap reduction across all tested cases: 80%. The mechanism holds even with pessimistic process assumptions.
A40: People test: how much value is lost when operators dismiss alerts?
A41: Share of drift episodes where alerts are dismissed | B41: Scrap reduction vs today
A42: 0 | B42: 0.93929302
A43: 0.1 | B43: 0.84457608
A44: 0.2 | B44: 0.7497195
A45: 0.31 | B45: 0.64310602
...

Sheet Simulation3
A1: Idea tests: simulation results (values produced by run_tests.py, not formulas)
A2: Re-run run_tests.py after changing assumptions. Process parameters below are illustrative assumptions, not TMMIN data: present them as a mechanism test, and show the sensitivity.
